I'm sorry, but an uncaught exception occurred.

While running game code:
  File "game/script.rpy", line 80, in script
    "хело"
IOError: [Errno 9] Bad file descriptor

-- Full Traceback ------------------------------------------------------------

Full traceback:
  File "C:\Programs\renpy-6.18.3-sdk\renpy\bootstrap.py", line 289, in bootstrap
    renpy.main.main()
  File "C:\Programs\renpy-6.18.3-sdk\renpy\main.py", line 357, in main
    run(restart)
  File "C:\Programs\renpy-6.18.3-sdk\renpy\main.py", line 77, in run
    renpy.execution.run_context(True)
  File "C:\Programs\renpy-6.18.3-sdk\renpy\execution.py", line 598, in run_context
    context.run()
  File "game/script.rpy", line 80, in script
    "хело"
  File "C:\Programs\renpy-6.18.3-sdk\renpy\error.py", line 197, in report_exception
    sys.stdout.write(full.getvalue())
IOError: [Errno 9] Bad file descriptor

Windows-7-6.1.7601-SP1
Ren'Py 6.18.3.761
Good Fortune 0.0
